mtprotosender.py:228 #INFO     [2025-10-04 20:01:47,842] - telethon.network.mtprotosender - 0| Connecting to 149.154.167.51:443/TcpFull...
mtprotosender.py:279 #INFO     [2025-10-04 20:01:47,877] - telethon.network.mtprotosender - 0| Connection to 149.154.167.51:443/TcpFull complete!
handlers.py:99 #INFO     [2025-10-04 20:02:16,829] - root - 0| Handler called. MessageDeleted
updates.py:590 #ERROR    [2025-10-04 20:02:17,043] - telethon.client.updates - 0| Unhandled exception on event_message_deleted
Traceback (most recent call last):
  File "C:\Users\Valentyn\PycharmProjects\tgbot-microservice\.venv\lib\site-packages\telethon\client\updates.py", line 574, in _dispatch_update
    await callback(event)
  File "C:\Users\Valentyn\PycharmProjects\tgbot-microservice\app\handlers.py", line 109, in event_message_deleted
    deleted_by, topic_id = await Ut.get_userdata_deleted_by(message_ids=message_ids, input_chat=input_chat)
TypeError: cannot unpack non-iterable NoneType object
mtprotosender.py:319 #INFO     [2025-10-04 20:02:52,198] - telethon.network.mtprotosender - 0| Disconnecting from 149.154.167.51:443/TcpFull...
mtprotosender.py:339 #INFO     [2025-10-04 20:02:52,198] - telethon.network.mtprotosender - 0| Disconnection from 149.154.167.51:443/TcpFull complete!
