mtprotosender.py:228 #INFO     [2025-10-07 22:25:36,861] - telethon.network.mtprotosender - 0| Connecting to 149.154.167.92:443/TcpFull...
mtprotosender.py:279 #INFO     [2025-10-07 22:25:36,899] - telethon.network.mtprotosender - 0| Connection to 149.154.167.92:443/TcpFull complete!
utils.py:67 #INFO     [2025-10-07 22:25:37,372] - root - 0| Client has been connected!
utils.py:67 #INFO     [2025-10-07 22:25:37,372] - root - 0| Redis has been initialized!
utils.py:67 #INFO     [2025-10-07 22:25:37,372] - root - 0| Prepare to load data in redis...
utils.py:67 #INFO     [2025-10-07 22:25:37,372] - root - 0| Loading messages data from small groups...
utils.py:67 #INFO     [2025-10-07 22:25:38,159] - root - 0| Data from small groups has been loaded!
utils.py:67 #INFO     [2025-10-07 22:25:38,160] - root - 0| Event handlers has been registered!
utils.py:67 #INFO     [2025-10-07 22:25:38,160] - root - 0| Events worker 0 has been started!
utils.py:67 #INFO     [2025-10-07 22:25:38,160] - root - 0| Commands worker 0 has been started!
updates.py:590 #ERROR    [2025-10-07 22:25:40,347] - telethon.client.updates - 0| Unhandled exception on event_new_message
Traceback (most recent call last):
  File "C:\Users\Valentyn\PycharmProjects\tgbot-microservice\.venv\lib\site-packages\telethon\client\updates.py", line 574, in _dispatch_update
    await callback(event)
  File "C:\Users\Valentyn\PycharmProjects\tgbot-microservice\app\tg\events_catcher.py", line 36, in event_new_message
    if topic_id and (topic_id + 1 == event.message.id):
TypeError: can only concatenate tuple (not "int") to tuple
mtprotosender.py:319 #INFO     [2025-10-07 22:25:44,484] - telethon.network.mtprotosender - 0| Disconnecting from 149.154.167.92:443/TcpFull...
mtprotosender.py:339 #INFO     [2025-10-07 22:25:44,484] - telethon.network.mtprotosender - 0| Disconnection from 149.154.167.92:443/TcpFull complete!
