mtprotosender.py:228 #INFO     [2025-09-24 16:33:50,961] - telethon.network.mtprotosender - 0| Connecting to 149.154.167.51:443/TcpFull...
mtprotosender.py:279 #INFO     [2025-09-24 16:33:51,170] - telethon.network.mtprotosender - 0| Connection to 149.154.167.51:443/TcpFull complete!
handlers.py:15 #INFO     [2025-09-24 16:33:59,414] - root - 0| Handler called. NewMessage. type = <class 'telethon.tl.patched.Message'>
updates.py:590 #ERROR    [2025-09-24 16:34:00,261] - telethon.client.updates - 0| Unhandled exception on event_new_message
Traceback (most recent call last):
  File "C:\Users\Valentyn\AppData\Local\Programs\Python\Python310\lib\site-packages\telethon\client\updates.py", line 574, in _dispatch_update
    await callback(event)
  File "D:\PythonProjects\tgbot-microservice\app\handlers.py", line 46, in event_new_message
    sender=FromUser(
  File "C:\Users\Valentyn\AppData\Local\Programs\Python\Python310\lib\site-packages\pydantic\main.py", line 253, in __init__
    validated_self = self.__pydantic_validator__.validate_python(data, self_instance=self)
pydantic_core._pydantic_core.ValidationError: 1 validation error for FromUser
language_code
  Input should be a valid string [type=string_type, input_value=None, input_type=NoneType]
    For further information visit https://errors.pydantic.dev/2.11/v/string_type
mtprotosender.py:319 #INFO     [2025-09-24 16:34:02,943] - telethon.network.mtprotosender - 0| Disconnecting from 149.154.167.51:443/TcpFull...
mtprotosender.py:339 #INFO     [2025-09-24 16:34:02,944] - telethon.network.mtprotosender - 0| Disconnection from 149.154.167.51:443/TcpFull complete!
base_events.py:1758 #ERROR    [2025-09-24 16:34:02,975] - asyncio - 0| Unclosed client session
client_session: <aiohttp.client.ClientSession object at 0x000001DF8D6393C0>
