mtprotosender.py:228 #INFO     [2025-10-05 17:41:04,722] - telethon.network.mtprotosender - 0| Connecting to 149.154.167.51:443/TcpFull...
mtprotosender.py:279 #INFO     [2025-10-05 17:41:04,757] - telethon.network.mtprotosender - 0| Connection to 149.154.167.51:443/TcpFull complete!
utils.py:63 #INFO     [2025-10-05 17:41:05,026] - root - 0| Client has been connected!
utils.py:63 #INFO     [2025-10-05 17:41:05,185] - root - 0| Redis has been initialized!
utils.py:63 #INFO     [2025-10-05 17:41:05,259] - root - 0| Prepare to load data in redis...
utils.py:63 #INFO     [2025-10-05 17:41:05,361] - root - 0| Loading messages data from small groups...
utils.py:63 #INFO     [2025-10-05 17:41:14,210] - root - 0| Data from small groups has been loaded!
utils.py:63 #INFO     [2025-10-05 17:41:14,267] - root - 0| Event handlers has been registered!
utils.py:63 #INFO     [2025-10-05 17:41:15,356] - root - 0| Event called. <class 'telethon.events.messagedeleted.MessageDeleted.Event'>
updates.py:590 #ERROR    [2025-10-05 17:41:15,457] - telethon.client.updates - 0| Unhandled exception on event_message_deleted
Traceback (most recent call last):
  File "C:\Users\Valentyn\PycharmProjects\tgbot-microservice\.venv\lib\site-packages\telethon\client\updates.py", line 574, in _dispatch_update
    await callback(event)
  File "C:\Users\Valentyn\PycharmProjects\tgbot-microservice\app\handlers.py", line 146, in event_message_deleted
    chat_id, chat_info = await ChatInfo.obj_from_peer(PeerChat(chat_id=int(chat_id[1:])))
  File "C:\Users\Valentyn\PycharmProjects\tgbot-microservice\app\api_interface.py", line 52, in obj_from_peer
    full_chat = await Config.TG_CLIENT(GetFullChatRequest(peer_id))
  File "C:\Users\Valentyn\PycharmProjects\tgbot-microservice\.venv\lib\site-packages\telethon\client\users.py", line 30, in __call__
    return await self._call(self._sender, request, ordered=ordered)
  File "C:\Users\Valentyn\PycharmProjects\tgbot-microservice\.venv\lib\site-packages\telethon\client\users.py", line 92, in _call
    result = await future
telethon.errors.rpcerrorlist.ChatIdInvalidError: Invalid object ID for a chat. Make sure to pass the right types, for instance making sure that the request is designed for chats (not channels/megagroups) or otherwise look for a different one more suited\nAn example working with a megagroup and AddChatUserRequest, it will fail because megagroups are channels. Use InviteToChannelRequest instead (caused by GetFullChatRequest)
utils.py:63 #INFO     [2025-10-05 17:41:15,458] - root - 0| Event called. <class 'telethon.tl.types.UpdateDeleteMessages'>
utils.py:63 #INFO     [2025-10-05 17:41:15,968] - root - 0| Event called. <class 'telethon.tl.types.UpdateUserStatus'>
utils.py:63 #INFO     [2025-10-05 17:41:16,046] - root - 0| Event called. <class 'telethon.events.newmessage.NewMessage.Event'>
api_interface.py:236 #INFO     [2025-10-05 17:41:16,366] - root - 0| 200 | https://tenerife.chat/chat/webhook/telegram/create | {'success': True, 'method': 'create'}
utils.py:63 #INFO     [2025-10-05 17:41:16,367] - root - 0| Event called. <class 'telethon.tl.types.UpdateNewChannelMessage'>
utils.py:63 #INFO     [2025-10-05 17:41:20,235] - root - 0| Event called. <class 'telethon.events.messageedited.MessageEdited.Event'>
utils.py:63 #INFO     [2025-10-05 17:41:20,237] - root - 0| Event called. <class 'telethon.events.newmessage.NewMessage.Event'>
api_interface.py:236 #INFO     [2025-10-05 17:41:20,449] - root - 0| 200 | https://tenerife.chat/chat/webhook/telegram/update | {'success': True, 'method': 'update'}
utils.py:63 #INFO     [2025-10-05 17:41:20,449] - root - 0| Event called. <class 'telethon.tl.types.UpdateEditChannelMessage'>
api_interface.py:236 #INFO     [2025-10-05 17:41:20,536] - root - 0| 200 | https://tenerife.chat/chat/webhook/telegram/create | {'success': True, 'method': 'create'}
utils.py:63 #INFO     [2025-10-05 17:41:20,536] - root - 0| Event called. <class 'telethon.tl.types.UpdateNewChannelMessage'>
mtprotosender.py:319 #INFO     [2025-10-05 17:41:21,323] - telethon.network.mtprotosender - 0| Disconnecting from 149.154.167.51:443/TcpFull...
mtprotosender.py:339 #INFO     [2025-10-05 17:41:21,323] - telethon.network.mtprotosender - 0| Disconnection from 149.154.167.51:443/TcpFull complete!
