mtprotosender.py:228 #INFO     [2025-10-04 20:02:53,620] - telethon.network.mtprotosender - 0| Connecting to 149.154.167.51:443/TcpFull...
mtprotosender.py:279 #INFO     [2025-10-04 20:02:53,654] - telethon.network.mtprotosender - 0| Connection to 149.154.167.51:443/TcpFull complete!
handlers.py:99 #INFO     [2025-10-04 20:03:01,407] - root - 0| Handler called. MessageDeleted
api_interface.py:237 #INFO     [2025-10-04 20:03:01,913] - venv - 0| 200 | https://tenerife.chat/chat/webhook/telegram/delete | {'success': True, 'method': 'delete'}
handlers.py:99 #INFO     [2025-10-04 20:03:10,313] - root - 0| Handler called. MessageDeleted
updates.py:590 #ERROR    [2025-10-04 20:03:10,513] - telethon.client.updates - 0| Unhandled exception on event_message_deleted
Traceback (most recent call last):
  File "C:\Users\Valentyn\PycharmProjects\tgbot-microservice\.venv\lib\site-packages\telethon\client\updates.py", line 574, in _dispatch_update
    await callback(event)
  File "C:\Users\Valentyn\PycharmProjects\tgbot-microservice\app\handlers.py", line 109, in event_message_deleted
    deleted_by, topic_id = await Ut.get_userdata_deleted_by(message_ids=message_ids, input_chat=input_chat)
TypeError: cannot unpack non-iterable NoneType object
handlers.py:99 #INFO     [2025-10-04 20:03:42,052] - root - 0| Handler called. MessageDeleted
updates.py:590 #ERROR    [2025-10-04 20:03:43,217] - telethon.client.updates - 0| Unhandled exception on event_message_deleted
Traceback (most recent call last):
  File "C:\Users\Valentyn\PycharmProjects\tgbot-microservice\.venv\lib\site-packages\telethon\client\updates.py", line 574, in _dispatch_update
    await callback(event)
  File "C:\Users\Valentyn\PycharmProjects\tgbot-microservice\app\handlers.py", line 120, in event_message_deleted
    req_model=MessageDeleted(
  File "C:\Users\Valentyn\PycharmProjects\tgbot-microservice\.venv\lib\site-packages\pydantic\main.py", line 253, in __init__
    validated_self = self.__pydantic_validator__.validate_python(data, self_instance=self)
pydantic_core._pydantic_core.ValidationError: 1 validation error for MessageDeleted
topic_id
  Input should be a valid integer [type=int_type, input_value=None, input_type=NoneType]
    For further information visit https://errors.pydantic.dev/2.11/v/int_type
mtprotosender.py:319 #INFO     [2025-10-04 20:04:00,434] - telethon.network.mtprotosender - 0| Disconnecting from 149.154.167.51:443/TcpFull...
mtprotosender.py:339 #INFO     [2025-10-04 20:04:00,434] - telethon.network.mtprotosender - 0| Disconnection from 149.154.167.51:443/TcpFull complete!
