mtprotosender.py:228 #INFO     [2025-10-03 19:58:54,857] - telethon.network.mtprotosender - 0| Connecting to 149.154.167.51:443/TcpFull...
mtprotosender.py:279 #INFO     [2025-10-03 19:58:54,895] - telethon.network.mtprotosender - 0| Connection to 149.154.167.51:443/TcpFull complete!
handlers.py:115 #INFO     [2025-10-03 19:59:04,852] - root - 0| Handler called. ChatAction
handlers.py:115 #INFO     [2025-10-03 19:59:08,400] - root - 0| Handler called. ChatAction
updates.py:590 #ERROR    [2025-10-03 19:59:08,633] - telethon.client.updates - 0| Unhandled exception on event_chat_action
Traceback (most recent call last):
  File "C:\Users\Valentyn\PycharmProjects\tgbot-microservice\.venv\lib\site-packages\telethon\client\updates.py", line 574, in _dispatch_update
    await callback(event)
  File "C:\Users\Valentyn\PycharmProjects\tgbot-microservice\app\handlers.py", line 122, in event_chat_action
    chat_id, chat_info = await ChatInfo.obj_from_peer(act_msg.peer_id)
  File "C:\Users\Valentyn\PycharmProjects\tgbot-microservice\app\api_interface.py", line 64, in obj_from_peer
    member_count=full_chat.full_chat.participants_count
AttributeError: 'ChatFull' object has no attribute 'participants_count'
mtprotosender.py:319 #INFO     [2025-10-03 19:59:50,428] - telethon.network.mtprotosender - 0| Disconnecting from 149.154.167.51:443/TcpFull...
mtprotosender.py:339 #INFO     [2025-10-03 19:59:50,428] - telethon.network.mtprotosender - 0| Disconnection from 149.154.167.51:443/TcpFull complete!
