mtprotosender.py:228 #INFO     [2025-10-05 18:23:23,943] - telethon.network.mtprotosender - 0| Connecting to 149.154.167.92:443/TcpFull...
mtprotosender.py:279 #INFO     [2025-10-05 18:23:23,978] - telethon.network.mtprotosender - 0| Connection to 149.154.167.92:443/TcpFull complete!
utils.py:64 #INFO     [2025-10-05 18:23:24,365] - root - 0| Client has been connected!
utils.py:64 #INFO     [2025-10-05 18:23:24,366] - root - 0| Redis has been initialized!
utils.py:64 #INFO     [2025-10-05 18:23:24,366] - root - 0| Prepare to load data in redis...
utils.py:64 #INFO     [2025-10-05 18:23:24,366] - root - 0| Loading messages data from small groups...
utils.py:64 #INFO     [2025-10-05 18:23:24,437] - root - 0| Data from small groups has been loaded!
utils.py:64 #INFO     [2025-10-05 18:23:24,437] - root - 0| Event handlers has been registered!
utils.py:64 #INFO     [2025-10-05 18:23:39,661] - root - 0| Event called: ChatAction. action: MessageActionChatAddUser
api_interface.py:236 #INFO     [2025-10-05 18:23:40,100] - root - 0| 200 | https://tenerife.chat/chat/webhook/telegram/bot_added | {'success': True, 'method': 'bot_added'}
utils.py:64 #INFO     [2025-10-05 18:23:47,943] - root - 0| Event called. NewMessage
updates.py:590 #ERROR    [2025-10-05 18:23:48,197] - telethon.client.updates - 0| Unhandled exception on event_new_message
Traceback (most recent call last):
  File "C:\Users\Valentyn\PycharmProjects\tgbot-microservice\.venv\lib\site-packages\telethon\client\updates.py", line 574, in _dispatch_update
    await callback(event)
  File "C:\Users\Valentyn\PycharmProjects\tgbot-microservice\app\handlers.py", line 28, in event_new_message
    await Config.REDIS.set(f"msg:{msg_obj.id}", chat_id)
  File "C:\Users\Valentyn\PycharmProjects\tgbot-microservice\.venv\lib\site-packages\redis\asyncio\client.py", line 677, in execute_command
    return await conn.retry.call_with_retry(
  File "C:\Users\Valentyn\PycharmProjects\tgbot-microservice\.venv\lib\site-packages\redis\asyncio\retry.py", line 50, in call_with_retry
    return await do()
  File "C:\Users\Valentyn\PycharmProjects\tgbot-microservice\.venv\lib\site-packages\redis\asyncio\client.py", line 652, in _send_command_parse_response
    return await self.parse_response(conn, command_name, **options)
  File "C:\Users\Valentyn\PycharmProjects\tgbot-microservice\.venv\lib\site-packages\redis\asyncio\client.py", line 698, in parse_response
    response = await connection.read_response()
  File "C:\Users\Valentyn\PycharmProjects\tgbot-microservice\.venv\lib\site-packages\redis\asyncio\connection.py", line 627, in read_response
    raise response from None
redis.exceptions.ResponseError: MISCONF Redis is configured to save RDB snapshots, but is currently not able to persist on disk. Commands that may modify the data set are disabled. Please check Redis logs for details about the error.
mtprotosender.py:319 #INFO     [2025-10-05 18:23:52,639] - telethon.network.mtprotosender - 0| Disconnecting from 149.154.167.92:443/TcpFull...
mtprotosender.py:339 #INFO     [2025-10-05 18:23:52,639] - telethon.network.mtprotosender - 0| Disconnection from 149.154.167.92:443/TcpFull complete!
