mtprotosender.py:228 #INFO     [2025-09-25 01:41:00,964] - telethon.network.mtprotosender - 0| Connecting to 149.154.167.51:443/TcpFull...
mtprotosender.py:279 #INFO     [2025-09-25 01:41:01,002] - telethon.network.mtprotosender - 0| Connection to 149.154.167.51:443/TcpFull complete!
handlers.py:18 #INFO     [2025-09-25 01:41:04,414] - root - 0| Handler called. NewMessage. type = <class 'telethon.tl.patched.Message'>
updates.py:590 #ERROR    [2025-09-25 01:41:04,478] - telethon.client.updates - 0| Unhandled exception on event_new_message
Traceback (most recent call last):
  File "C:\Users\Valentyn\PycharmProjects\tgbot-microservice\.venv\lib\site-packages\telethon\client\updates.py", line 574, in _dispatch_update
    await callback(event)
  File "C:\Users\Valentyn\PycharmProjects\tgbot-microservice\app\handlers.py", line 73, in event_new_message
    sticker_set_res = Config.TG_CLIENT(GetStickerSetRequest(stickerset=attr.stickerset))
TypeError: GetStickerSetRequest.__init__() missing 1 required positional argument: 'hash'
mtprotosender.py:319 #INFO     [2025-09-25 01:47:57,728] - telethon.network.mtprotosender - 0| Disconnecting from 149.154.167.51:443/TcpFull...
mtprotosender.py:339 #INFO     [2025-09-25 01:47:57,728] - telethon.network.mtprotosender - 0| Disconnection from 149.154.167.51:443/TcpFull complete!
base_events.py:1758 #ERROR    [2025-09-25 01:47:57,777] - asyncio - 0| Unclosed client session
client_session: <aiohttp.client.ClientSession object at 0x0000018A37EFA530>
