mtprotosender.py:228 #INFO     [2025-09-24 16:36:40,877] - telethon.network.mtprotosender - 0| Connecting to 149.154.167.51:443/TcpFull...
mtprotosender.py:279 #INFO     [2025-09-24 16:36:40,940] - telethon.network.mtprotosender - 0| Connection to 149.154.167.51:443/TcpFull complete!
handlers.py:15 #INFO     [2025-09-24 16:36:47,145] - root - 0| Handler called. NewMessage. type = <class 'telethon.tl.patched.Message'>
handlers.py:15 #INFO     [2025-09-24 16:36:47,147] - root - 0| Handler called. NewMessage. type = <class 'telethon.tl.patched.Message'>
handlers.py:15 #INFO     [2025-09-24 16:36:49,398] - root - 0| Handler called. NewMessage. type = <class 'telethon.tl.patched.Message'>
handlers.py:15 #INFO     [2025-09-24 16:36:57,797] - root - 0| Handler called. NewMessage. type = <class 'telethon.tl.patched.Message'>
handlers.py:15 #INFO     [2025-09-24 16:36:57,801] - root - 0| Handler called. NewMessage. type = <class 'telethon.tl.patched.Message'>
updates.py:590 #ERROR    [2025-09-24 16:36:58,029] - telethon.client.updates - 0| Unhandled exception on event_new_message
Traceback (most recent call last):
  File "C:\Users\Valentyn\AppData\Local\Programs\Python\Python310\lib\site-packages\telethon\client\updates.py", line 574, in _dispatch_update
    await callback(event)
  File "D:\PythonProjects\tgbot-microservice\app\handlers.py", line 47, in event_new_message
    topic_id=msg_obj.reply_to.reply_to_top_id,
AttributeError: 'NoneType' object has no attribute 'reply_to_top_id'
handlers.py:15 #INFO     [2025-09-24 16:37:01,548] - root - 0| Handler called. NewMessage. type = <class 'telethon.tl.patched.Message'>
mtprotosender.py:319 #INFO     [2025-09-24 16:37:03,790] - telethon.network.mtprotosender - 0| Disconnecting from 149.154.167.51:443/TcpFull...
mtprotosender.py:339 #INFO     [2025-09-24 16:37:03,790] - telethon.network.mtprotosender - 0| Disconnection from 149.154.167.51:443/TcpFull complete!
base_events.py:1758 #ERROR    [2025-09-24 16:37:03,824] - asyncio - 0| Unclosed client session
client_session: <aiohttp.client.ClientSession object at 0x0000019D50919360>
base_events.py:1758 #ERROR    [2025-09-24 16:37:03,824] - asyncio - 0| Unclosed connector
connections: ['deque([(<aiohttp.client_proto.ResponseHandler object at 0x0000019D50952F20>, 532566.265), (<aiohttp.client_proto.ResponseHandler object at 0x0000019D50952CE0>, 532570.062)])']
connector: <aiohttp.connector.TCPConnector object at 0x0000019D50919F00>
base_events.py:1758 #ERROR    [2025-09-24 16:37:03,825] - asyncio - 0| Fatal error on SSL transport
protocol: <asyncio.sslproto.SSLProtocol object at 0x0000019D5099DDE0>
transport: <_ProactorSocketTransport fd=952 read=<_OverlappedFuture cancelled>>
Traceback (most recent call last):
  File "C:\Users\Valentyn\AppData\Local\Programs\Python\Python310\lib\asyncio\sslproto.py", line 690, in _process_write_backlog
    self._transport.write(chunk)
  File "C:\Users\Valentyn\AppData\Local\Programs\Python\Python310\lib\asyncio\proactor_events.py", line 365, in write
    self._loop_writing(data=bytes(data))
  File "C:\Users\Valentyn\AppData\Local\Programs\Python\Python310\lib\asyncio\proactor_events.py", line 401, in _loop_writing
    self._write_fut = self._loop._proactor.send(self._sock, data)
AttributeError: 'NoneType' object has no attribute 'send'
base_events.py:1758 #ERROR    [2025-09-24 16:37:03,825] - asyncio - 0| Fatal error on SSL transport
protocol: <asyncio.sslproto.SSLProtocol object at 0x0000019D5091A140>
transport: <_ProactorSocketTransport fd=924 read=<_OverlappedFuture cancelled>>
Traceback (most recent call last):
  File "C:\Users\Valentyn\AppData\Local\Programs\Python\Python310\lib\asyncio\sslproto.py", line 690, in _process_write_backlog
    self._transport.write(chunk)
  File "C:\Users\Valentyn\AppData\Local\Programs\Python\Python310\lib\asyncio\proactor_events.py", line 365, in write
    self._loop_writing(data=bytes(data))
  File "C:\Users\Valentyn\AppData\Local\Programs\Python\Python310\lib\asyncio\proactor_events.py", line 401, in _loop_writing
    self._write_fut = self._loop._proactor.send(self._sock, data)
AttributeError: 'NoneType' object has no attribute 'send'
